2025-05-31 17:14:13,535 | WATCHDOG | INFO | CoreFlow Watchdog starting
2025-05-31 17:14:13,535 | WATCHDOG | INFO | Starting process: /opt/coreflow/.venv/bin/python3 /opt/coreflow/emitter/signal_emitter.py
2025-05-31 17:14:13,563 | WATCHDOG | ERROR | 2025-05-31 17:14:13,563 - FTMO_Stable - Stable FTMO Emitter initialized - FTMO_Stable
2025-05-31 17:14:13,563 | WATCHDOG | ERROR | 2025-05-31 17:14:13,563 - FTMO_Stable - Created trade_entry signal for EURUSD
2025-05-31 17:14:13,563 | WATCHDOG | ERROR | 2025-05-31 17:14:13,563 - FTMO_Stable - Starting stable emitter (interval: 30s)
2025-05-31 17:14:13,563 | WATCHDOG | ERROR | 2025-05-31 17:14:13,563 - FTMO_Stable - Created heartbeat signal for SYSTEM
2025-05-31 17:14:43,563 | WATCHDOG | ERROR | 2025-05-31 17:14:43,563 - FTMO_Stable - Created heartbeat signal for SYSTEM
2025-05-31 17:15:13,564 | WATCHDOG | ERROR | 2025-05-31 17:15:13,563 - FTMO_Stable - Created heartbeat signal for SYSTEM
2025-05-31 17:15:43,564 | WATCHDOG | ERROR | 2025-05-31 17:15:43,564 - FTMO_Stable - Created heartbeat signal for SYSTEM
2025-05-31 17:16:13,564 | WATCHDOG | ERROR | 2025-05-31 17:16:13,564 - FTMO_Stable - Created heartbeat signal for SYSTEM
2025-05-31 17:16:43,564 | WATCHDOG | ERROR | 2025-05-31 17:16:43,564 - FTMO_Stable - Created heartbeat signal for SYSTEM
2025-05-31 17:17:12,940 | WATCHDOG | INFO | Shutdown requested by user
2025-05-31 17:17:12,940 | WATCHDOG | INFO | Stopping process...
2025-05-31 17:17:12,941 | WATCHDOG | INFO | Watchdog stopped
2025-05-31 17:54:37.729 | CF-WATCHDOG | INFO     | üì° CoreFlow Watchdog gestartet
2025-05-31 17:54:37.777 | CF-WATCHDOG | INFO     | Process gestartet (PID: 462048)
2025-05-31 17:54:44.296 | CF-WATCHDOG | INFO     | ‚õî Manuell beendet
2025-05-31 17:54:44.326 | CF-WATCHDOG | INFO     | ‚úÖ Watchdog gestoppt
2025-05-31 17:58:05,704 | CF-WATCHDOG | INFO     | üì° CoreFlow Watchdog gestartet
2025-05-31 17:58:05,705 | CF-WATCHDOG | WARNING  | ‚ö†Ô∏è Prozess gestoppt ‚Äì versuche Neustart
2025-05-31 17:58:05,705 | CF-WATCHDOG | INFO     | üöÄ Prozess gestartet: /opt/coreflow/coreflow_main.py
2025-05-31 17:58:12,654 | CF-WATCHDOG | INFO     | üõë Watchdog beendet durch Nutzer
2025-05-31 18:00:46,140 | CF-WATCHDOG | INFO     | üì° CoreFlow Watchdog gestartet
2025-05-31 18:00:46,140 | CF-WATCHDOG | WARNING  | ‚ö†Ô∏è Prozess gestoppt ‚Äì versuche Neustart
2025-05-31 18:00:46,141 | CF-WATCHDOG | INFO     | üöÄ Prozess gestartet: /opt/coreflow/coreflow_main.py
2025-05-31 18:00:56,141 | CF-WATCHDOG | WARNING  | ‚ö†Ô∏è Prozess gestoppt ‚Äì versuche Neustart
2025-05-31 18:00:56,143 | CF-WATCHDOG | INFO     | üöÄ Prozess gestartet: /opt/coreflow/coreflow_main.py
2025-05-31 18:00:58,370 | CF-WATCHDOG | INFO     | üõë Watchdog beendet durch Nutzer
2025-05-31 18:02:41,304 | CF-WATCHDOG | INFO     | üì° CoreFlow Watchdog gestartet
2025-05-31 18:02:41,305 | CF-WATCHDOG | WARNING  | ‚ö†Ô∏è Prozess gestoppt ‚Äì versuche Neustart
2025-05-31 18:02:41,305 | CF-WATCHDOG | INFO     | üöÄ Prozess gestartet: /opt/coreflow/coreflow_main.py
2025-05-31 18:02:46,046 | CF-WATCHDOG | INFO     | üõë Watchdog beendet durch Nutzer
2025-05-31 18:04:35,200 | CF-WATCHDOG | INFO     | üì° CoreFlow Watchdog gestartet
2025-05-31 18:04:35,201 | CF-WATCHDOG | WARNING  | ‚ö†Ô∏è Prozess gestoppt ‚Äì versuche Neustart
2025-05-31 18:04:35,201 | CF-WATCHDOG | INFO     | üöÄ Prozess gestartet: /opt/coreflow/coreflow_main.py
2025-05-31 18:04:45,202 | CF-WATCHDOG | WARNING  | ‚ö†Ô∏è Prozess gestoppt ‚Äì versuche Neustart
2025-05-31 18:04:45,203 | CF-WATCHDOG | INFO     | üöÄ Prozess gestartet: /opt/coreflow/coreflow_main.py
2025-05-31 18:04:55,204 | CF-WATCHDOG | WARNING  | ‚ö†Ô∏è Prozess gestoppt ‚Äì versuche Neustart
2025-05-31 18:04:55,205 | CF-WATCHDOG | INFO     | üöÄ Prozess gestartet: /opt/coreflow/coreflow_main.py
2025-05-31 18:05:05,206 | CF-WATCHDOG | WARNING  | ‚ö†Ô∏è Prozess gestoppt ‚Äì versuche Neustart
2025-05-31 18:05:05,207 | CF-WATCHDOG | INFO     | üöÄ Prozess gestartet: /opt/coreflow/coreflow_main.py
2025-05-31 18:05:11,753 | CF-WATCHDOG | INFO     | üõë Watchdog beendet durch Nutzer
2025-05-31 18:08:13,623 | CF-WATCHDOG | INFO     | üì° CoreFlow Watchdog gestartet
2025-05-31 18:08:13,624 | CF-WATCHDOG | WARNING  | ‚ö†Ô∏è Prozess gestoppt ‚Äì versuche Neustart
2025-05-31 18:08:13,624 | CF-WATCHDOG | INFO     | üöÄ Prozess gestartet: /opt/coreflow/coreflow_main.py
2025-05-31 18:08:20,023 | CF-WATCHDOG | INFO     | üõë Watchdog beendet durch Nutzer
2025-05-31 18:08:46,428 | CF-WATCHDOG | INFO     | üì° CoreFlow Watchdog gestartet
2025-05-31 18:08:46,429 | CF-WATCHDOG | WARNING  | ‚ö†Ô∏è Prozess gestoppt ‚Äì versuche Neustart
2025-05-31 18:08:46,429 | CF-WATCHDOG | INFO     | üöÄ Prozess gestartet: /opt/coreflow/coreflow_main.py
2025-05-31 18:08:56,429 | CF-WATCHDOG | WARNING  | ‚ö†Ô∏è Prozess gestoppt ‚Äì versuche Neustart
2025-05-31 18:08:56,431 | CF-WATCHDOG | INFO     | üöÄ Prozess gestartet: /opt/coreflow/coreflow_main.py
2025-05-31 18:09:06,431 | CF-WATCHDOG | WARNING  | ‚ö†Ô∏è Prozess gestoppt ‚Äì versuche Neustart
2025-05-31 18:09:06,433 | CF-WATCHDOG | INFO     | üöÄ Prozess gestartet: /opt/coreflow/coreflow_main.py
2025-05-31 18:09:12,447 | CF-WATCHDOG | INFO     | üõë Watchdog beendet durch Nutzer
2025-05-31 18:12:04,784 | CF-WATCHDOG | INFO     | üì° CoreFlow Watchdog gestartet
2025-05-31 18:12:04,785 | CF-WATCHDOG | WARNING  | ‚ö†Ô∏è Prozess gestoppt ‚Äì versuche Neustart
2025-05-31 18:12:04,785 | CF-WATCHDOG | INFO     | üöÄ Prozess gestartet: /opt/coreflow/coreflow_main.py
2025-05-31 18:12:12,756 | CF-WATCHDOG | INFO     | üõë Watchdog beendet durch Nutzer
2025-05-31 18:12:42 | CF-WATCHDOG | INFO     | Process started (PID: 463625)
2025-05-31 18:12:42 | CF-WATCHDOG | ERROR    | PROCESS STDERR: Traceback (most recent call last):
2025-05-31 18:12:42 | CF-WATCHDOG | ERROR    | PROCESS STDERR: File "/opt/coreflow/coreflow_main.py", line 17, in <module>
2025-05-31 18:12:42 | CF-WATCHDOG | ERROR    | PROCESS STDERR: from core.strategy.valg_engine import FTMO_VALGEngine
2025-05-31 18:12:42 | CF-WATCHDOG | ERROR    | PROCESS STDERR: File "/opt/coreflow/core/strategy/valg_engine.py", line 1, in <module>
2025-05-31 18:12:42 | CF-WATCHDOG | ERROR    | PROCESS STDERR: import numpy as np
2025-05-31 18:12:42 | CF-WATCHDOG | ERROR    | PROCESS STDERR: ModuleNotFoundError: No module named 'numpy'
2025-05-31 18:12:52 | CF-WATCHDOG | WARNING  | Process terminated - Attempting restart
2025-05-31 18:12:52 | CF-WATCHDOG | INFO     | Process started (PID: 463650)
2025-05-31 18:12:52 | CF-WATCHDOG | ERROR    | PROCESS STDERR: Traceback (most recent call last):
2025-05-31 18:12:52 | CF-WATCHDOG | ERROR    | PROCESS STDERR: File "/opt/coreflow/coreflow_main.py", line 17, in <module>
2025-05-31 18:12:52 | CF-WATCHDOG | ERROR    | PROCESS STDERR: from core.strategy.valg_engine import FTMO_VALGEngine
2025-05-31 18:12:52 | CF-WATCHDOG | ERROR    | PROCESS STDERR: File "/opt/coreflow/core/strategy/valg_engine.py", line 1, in <module>
2025-05-31 18:12:52 | CF-WATCHDOG | ERROR    | PROCESS STDERR: import numpy as np
2025-05-31 18:12:52 | CF-WATCHDOG | ERROR    | PROCESS STDERR: ModuleNotFoundError: No module named 'numpy'
2025-05-31 18:13:02 | CF-WATCHDOG | WARNING  | Process terminated - Attempting restart
2025-05-31 18:13:02 | CF-WATCHDOG | INFO     | Process started (PID: 463662)
2025-05-31 18:13:02 | CF-WATCHDOG | ERROR    | PROCESS STDERR: Traceback (most recent call last):
2025-05-31 18:13:02 | CF-WATCHDOG | ERROR    | PROCESS STDERR: File "/opt/coreflow/coreflow_main.py", line 17, in <module>
2025-05-31 18:13:02 | CF-WATCHDOG | ERROR    | PROCESS STDERR: from core.strategy.valg_engine import FTMO_VALGEngine
2025-05-31 18:13:02 | CF-WATCHDOG | ERROR    | PROCESS STDERR: File "/opt/coreflow/core/strategy/valg_engine.py", line 1, in <module>
2025-05-31 18:13:02 | CF-WATCHDOG | ERROR    | PROCESS STDERR: import numpy as np
2025-05-31 18:13:02 | CF-WATCHDOG | ERROR    | PROCESS STDERR: ModuleNotFoundError: No module named 'numpy'
2025-05-31 18:13:12 | CF-WATCHDOG | WARNING  | Process terminated - Attempting restart
2025-05-31 18:13:12 | CF-WATCHDOG | INFO     | Process started (PID: 463673)
2025-05-31 18:13:12 | CF-WATCHDOG | ERROR    | PROCESS STDERR: Traceback (most recent call last):
2025-05-31 18:13:12 | CF-WATCHDOG | ERROR    | PROCESS STDERR: File "/opt/coreflow/coreflow_main.py", line 17, in <module>
2025-05-31 18:13:12 | CF-WATCHDOG | ERROR    | PROCESS STDERR: from core.strategy.valg_engine import FTMO_VALGEngine
2025-05-31 18:13:12 | CF-WATCHDOG | ERROR    | PROCESS STDERR: File "/opt/coreflow/core/strategy/valg_engine.py", line 1, in <module>
2025-05-31 18:13:12 | CF-WATCHDOG | ERROR    | PROCESS STDERR: import numpy as np
2025-05-31 18:13:12 | CF-WATCHDOG | ERROR    | PROCESS STDERR: ModuleNotFoundError: No module named 'numpy'
2025-05-31 18:13:16 | CF-WATCHDOG | INFO     | Watchdog shutdown requested
2025-05-31 18:13:16 | CF-WATCHDOG | INFO     | Watchdog service stopped
2025-05-31 18:19:18 | CF-WATCHDOG | INFO     | üöÄ Process started (PID: 464166)
2025-05-31 18:19:18 | CF-WATCHDOG | ERROR    | STDERR: Traceback (most recent call last):
2025-05-31 18:19:18 | CF-WATCHDOG | ERROR    | STDERR: File "/opt/coreflow/coreflow_main.py", line 17, in <module>
2025-05-31 18:19:18 | CF-WATCHDOG | ERROR    | STDERR: from core.strategy.valg_engine import FTMO_VALGEngine
2025-05-31 18:19:18 | CF-WATCHDOG | ERROR    | STDERR: File "/opt/coreflow/core/strategy/valg_engine.py", line 1, in <module>
2025-05-31 18:19:18 | CF-WATCHDOG | ERROR    | STDERR: import numpy as np
2025-05-31 18:19:18 | CF-WATCHDOG | ERROR    | STDERR: ModuleNotFoundError: No module named 'numpy'
2025-05-31 18:19:28 | CF-WATCHDOG | WARNING  | ‚ö†Ô∏è Prozess gestoppt ‚Äì versuche Neustart
2025-05-31 18:19:28 | CF-WATCHDOG | INFO     | üöÄ Process started (PID: 464192)
2025-05-31 18:19:28 | CF-WATCHDOG | ERROR    | STDERR: Traceback (most recent call last):
2025-05-31 18:19:28 | CF-WATCHDOG | ERROR    | STDERR: File "/opt/coreflow/coreflow_main.py", line 17, in <module>
2025-05-31 18:19:28 | CF-WATCHDOG | ERROR    | STDERR: from core.strategy.valg_engine import FTMO_VALGEngine
2025-05-31 18:19:28 | CF-WATCHDOG | ERROR    | STDERR: File "/opt/coreflow/core/strategy/valg_engine.py", line 1, in <module>
2025-05-31 18:19:28 | CF-WATCHDOG | ERROR    | STDERR: import numpy as np
2025-05-31 18:19:28 | CF-WATCHDOG | ERROR    | STDERR: ModuleNotFoundError: No module named 'numpy'
2025-05-31 18:19:35 | CF-WATCHDOG | INFO     | üõë Watchdog manuell beendet
2025-05-31 18:19:35 | CF-WATCHDOG | INFO     | üîö Watchdog Service beendet
2025-05-31 18:20:14 | CF-WATCHDOG | INFO     | üöÄ Process started (PID: 464294)
2025-05-31 18:20:14 | CF-WATCHDOG | ERROR    | STDERR: Traceback (most recent call last):
2025-05-31 18:20:14 | CF-WATCHDOG | ERROR    | STDERR: File "/opt/coreflow/coreflow_main.py", line 17, in <module>
2025-05-31 18:20:14 | CF-WATCHDOG | ERROR    | STDERR: from core.strategy.valg_engine import FTMO_VALGEngine
2025-05-31 18:20:14 | CF-WATCHDOG | ERROR    | STDERR: File "/opt/coreflow/core/strategy/valg_engine.py", line 1, in <module>
2025-05-31 18:20:14 | CF-WATCHDOG | ERROR    | STDERR: import numpy as np
2025-05-31 18:20:14 | CF-WATCHDOG | ERROR    | STDERR: ModuleNotFoundError: No module named 'numpy'
2025-05-31 18:20:24 | CF-WATCHDOG | WARNING  | ‚ö†Ô∏è Prozess gestoppt ‚Äì versuche Neustart
2025-05-31 18:20:24 | CF-WATCHDOG | INFO     | üöÄ Process started (PID: 464321)
2025-05-31 18:20:24 | CF-WATCHDOG | ERROR    | STDERR: Traceback (most recent call last):
2025-05-31 18:20:24 | CF-WATCHDOG | ERROR    | STDERR: File "/opt/coreflow/coreflow_main.py", line 17, in <module>
2025-05-31 18:20:24 | CF-WATCHDOG | ERROR    | STDERR: from core.strategy.valg_engine import FTMO_VALGEngine
2025-05-31 18:20:24 | CF-WATCHDOG | ERROR    | STDERR: File "/opt/coreflow/core/strategy/valg_engine.py", line 1, in <module>
2025-05-31 18:20:24 | CF-WATCHDOG | ERROR    | STDERR: import numpy as np
2025-05-31 18:20:24 | CF-WATCHDOG | ERROR    | STDERR: ModuleNotFoundError: No module named 'numpy'
2025-05-31 18:20:29 | CF-WATCHDOG | INFO     | üõë Watchdog manuell beendet
2025-05-31 18:20:29 | CF-WATCHDOG | INFO     | üîö Watchdog Service beendet
2025-05-31 18:21:11 | CF-WATCHDOG | INFO     | üöÄ Process started (PID: 464415)
2025-05-31 18:21:11 | CF-WATCHDOG | ERROR    | STDERR: Traceback (most recent call last):
2025-05-31 18:21:11 | CF-WATCHDOG | ERROR    | STDERR: File "/opt/coreflow/coreflow_main.py", line 17, in <module>
2025-05-31 18:21:11 | CF-WATCHDOG | ERROR    | STDERR: from core.strategy.valg_engine import FTMO_VALGEngine
2025-05-31 18:21:11 | CF-WATCHDOG | ERROR    | STDERR: File "/opt/coreflow/core/strategy/valg_engine.py", line 1, in <module>
2025-05-31 18:21:11 | CF-WATCHDOG | ERROR    | STDERR: import numpy as np
2025-05-31 18:21:11 | CF-WATCHDOG | ERROR    | STDERR: ModuleNotFoundError: No module named 'numpy'
2025-05-31 18:21:21 | CF-WATCHDOG | WARNING  | ‚ö†Ô∏è Prozess gestoppt ‚Äì versuche Neustart
2025-05-31 18:21:21 | CF-WATCHDOG | INFO     | üöÄ Process started (PID: 464424)
2025-05-31 18:21:21 | CF-WATCHDOG | ERROR    | STDERR: Traceback (most recent call last):
2025-05-31 18:21:21 | CF-WATCHDOG | ERROR    | STDERR: File "/opt/coreflow/coreflow_main.py", line 17, in <module>
2025-05-31 18:21:21 | CF-WATCHDOG | ERROR    | STDERR: from core.strategy.valg_engine import FTMO_VALGEngine
2025-05-31 18:21:21 | CF-WATCHDOG | ERROR    | STDERR: File "/opt/coreflow/core/strategy/valg_engine.py", line 1, in <module>
2025-05-31 18:21:21 | CF-WATCHDOG | ERROR    | STDERR: import numpy as np
2025-05-31 18:21:21 | CF-WATCHDOG | ERROR    | STDERR: ModuleNotFoundError: No module named 'numpy'
2025-05-31 18:21:28 | CF-WATCHDOG | INFO     | üõë Watchdog manuell beendet
2025-05-31 18:21:28 | CF-WATCHDOG | INFO     | üîö Watchdog Service beendet
2025-05-31 18:22:08 | CF-WATCHDOG | INFO     | üöÄ Process started (PID: 464545)
2025-05-31 18:22:08 | CF-WATCHDOG | ERROR    | STDERR: Traceback (most recent call last):
2025-05-31 18:22:08 | CF-WATCHDOG | ERROR    | STDERR: File "/opt/coreflow/coreflow_main.py", line 17, in <module>
2025-05-31 18:22:08 | CF-WATCHDOG | ERROR    | STDERR: from core.strategy.valg_engine import FTMO_VALGEngine
2025-05-31 18:22:08 | CF-WATCHDOG | ERROR    | STDERR: File "/opt/coreflow/core/strategy/valg_engine.py", line 1, in <module>
2025-05-31 18:22:08 | CF-WATCHDOG | ERROR    | STDERR: import numpy as np
2025-05-31 18:22:08 | CF-WATCHDOG | ERROR    | STDERR: ModuleNotFoundError: No module named 'numpy'
2025-05-31 18:22:18 | CF-WATCHDOG | WARNING  | ‚ö†Ô∏è Prozess gestoppt ‚Äì versuche Neustart
2025-05-31 18:22:18 | CF-WATCHDOG | INFO     | üöÄ Process started (PID: 464556)
2025-05-31 18:22:18 | CF-WATCHDOG | ERROR    | STDERR: Traceback (most recent call last):
2025-05-31 18:22:18 | CF-WATCHDOG | ERROR    | STDERR: File "/opt/coreflow/coreflow_main.py", line 17, in <module>
2025-05-31 18:22:18 | CF-WATCHDOG | ERROR    | STDERR: from core.strategy.valg_engine import FTMO_VALGEngine
2025-05-31 18:22:18 | CF-WATCHDOG | ERROR    | STDERR: File "/opt/coreflow/core/strategy/valg_engine.py", line 1, in <module>
2025-05-31 18:22:18 | CF-WATCHDOG | ERROR    | STDERR: import numpy as np
2025-05-31 18:22:18 | CF-WATCHDOG | ERROR    | STDERR: ModuleNotFoundError: No module named 'numpy'
2025-05-31 18:22:28 | CF-WATCHDOG | WARNING  | ‚ö†Ô∏è Prozess gestoppt ‚Äì versuche Neustart
2025-05-31 18:22:28 | CF-WATCHDOG | INFO     | üöÄ Process started (PID: 464582)
2025-05-31 18:22:28 | CF-WATCHDOG | ERROR    | STDERR: Traceback (most recent call last):
2025-05-31 18:22:28 | CF-WATCHDOG | ERROR    | STDERR: File "/opt/coreflow/coreflow_main.py", line 17, in <module>
2025-05-31 18:22:28 | CF-WATCHDOG | ERROR    | STDERR: from core.strategy.valg_engine import FTMO_VALGEngine
2025-05-31 18:22:28 | CF-WATCHDOG | ERROR    | STDERR: File "/opt/coreflow/core/strategy/valg_engine.py", line 1, in <module>
2025-05-31 18:22:28 | CF-WATCHDOG | ERROR    | STDERR: import numpy as np
2025-05-31 18:22:28 | CF-WATCHDOG | ERROR    | STDERR: ModuleNotFoundError: No module named 'numpy'
2025-05-31 18:22:38 | CF-WATCHDOG | WARNING  | ‚ö†Ô∏è Prozess gestoppt ‚Äì versuche Neustart
2025-05-31 18:22:38 | CF-WATCHDOG | INFO     | üöÄ Process started (PID: 464594)
2025-05-31 18:22:38 | CF-WATCHDOG | ERROR    | STDERR: Traceback (most recent call last):
2025-05-31 18:22:38 | CF-WATCHDOG | ERROR    | STDERR: File "/opt/coreflow/coreflow_main.py", line 17, in <module>
2025-05-31 18:22:38 | CF-WATCHDOG | ERROR    | STDERR: from core.strategy.valg_engine import FTMO_VALGEngine
2025-05-31 18:22:38 | CF-WATCHDOG | ERROR    | STDERR: File "/opt/coreflow/core/strategy/valg_engine.py", line 1, in <module>
2025-05-31 18:22:38 | CF-WATCHDOG | ERROR    | STDERR: import numpy as np
2025-05-31 18:22:38 | CF-WATCHDOG | ERROR    | STDERR: ModuleNotFoundError: No module named 'numpy'
2025-05-31 18:22:48 | CF-WATCHDOG | WARNING  | ‚ö†Ô∏è Prozess gestoppt ‚Äì versuche Neustart
2025-05-31 18:22:48 | CF-WATCHDOG | INFO     | üöÄ Process started (PID: 464605)
2025-05-31 18:22:48 | CF-WATCHDOG | ERROR    | STDERR: Traceback (most recent call last):
2025-05-31 18:22:48 | CF-WATCHDOG | ERROR    | STDERR: File "/opt/coreflow/coreflow_main.py", line 17, in <module>
2025-05-31 18:22:48 | CF-WATCHDOG | ERROR    | STDERR: from core.strategy.valg_engine import FTMO_VALGEngine
2025-05-31 18:22:48 | CF-WATCHDOG | ERROR    | STDERR: File "/opt/coreflow/core/strategy/valg_engine.py", line 1, in <module>
2025-05-31 18:22:48 | CF-WATCHDOG | ERROR    | STDERR: import numpy as np
2025-05-31 18:22:48 | CF-WATCHDOG | ERROR    | STDERR: ModuleNotFoundError: No module named 'numpy'
2025-05-31 18:22:58 | CF-WATCHDOG | WARNING  | ‚ö†Ô∏è Prozess gestoppt ‚Äì versuche Neustart
2025-05-31 18:22:58 | CF-WATCHDOG | INFO     | üöÄ Process started (PID: 464631)
2025-05-31 18:22:58 | CF-WATCHDOG | ERROR    | STDERR: Traceback (most recent call last):
2025-05-31 18:22:58 | CF-WATCHDOG | ERROR    | STDERR: File "/opt/coreflow/coreflow_main.py", line 17, in <module>
2025-05-31 18:22:58 | CF-WATCHDOG | ERROR    | STDERR: from core.strategy.valg_engine import FTMO_VALGEngine
2025-05-31 18:22:58 | CF-WATCHDOG | ERROR    | STDERR: File "/opt/coreflow/core/strategy/valg_engine.py", line 1, in <module>
2025-05-31 18:22:58 | CF-WATCHDOG | ERROR    | STDERR: import numpy as np
2025-05-31 18:22:58 | CF-WATCHDOG | ERROR    | STDERR: ModuleNotFoundError: No module named 'numpy'
2025-05-31 18:23:08 | CF-WATCHDOG | WARNING  | ‚ö†Ô∏è Prozess gestoppt ‚Äì versuche Neustart
2025-05-31 18:23:08 | CF-WATCHDOG | WARNING  | ‚ö†Ô∏è Restart-Limit erreicht ‚Äì Cooldown
2025-05-31 18:23:57 | CF-WATCHDOG | INFO     | üõë Watchdog manuell beendet
2025-05-31 18:23:57 | CF-WATCHDOG | INFO     | üîö Watchdog Service beendet
2025-05-31 18:27:07 | CF-WATCHDOG | ERROR    | ‚ùå Missing dependencies: numpy

Run: pip install numpy
2025-05-31 18:28:21 | CF-WATCHDOG | ERROR    | ‚ùå Missing dependencies: numpy

Run: pip install numpy
2025-05-31 18:30:44 | CF-WATCHDOG | ERROR    | ‚ùå Missing dependencies: numpy

Run: pip install numpy
2025-05-31 18:31:33 | CF-WATCHDOG | ERROR    | ‚ùå Missing dependencies: numpy

Run: pip install numpy
2025-05-31 18:32:06 | CF-WATCHDOG | ERROR    | ‚ùå Missing dependencies: numpy

Run: pip install numpy
2025-05-31 18:33:31 | CF-WATCHDOG | ERROR    | ‚ùå Missing dependencies: numpy

Run: pip install numpy
2025-05-31 18:34:18 | CF-WATCHDOG | CRITICAL | üí• Watchdog error: 'ProcessManager' object has no attribute '_cleanup_process'
2025-05-31 18:38:58 | CF-WATCHDOG | ERROR    | ‚ùå Missing dependencies: python-dotenv

Run: pip install python-dotenv
2025-05-31 18:40:46 | CF-WATCHDOG | ERROR    | ‚ùå Missing dependencies: python-dotenv

Run: pip install python-dotenv
2025-05-31 18:41:03 | CF-WATCHDOG | ERROR    | ‚ùå Missing dependencies: python-dotenv

Run: pip install python-dotenv
2025-05-31 18:42:45 | CF-WATCHDOG | ERROR    | ‚ùå Missing dependencies: python-dotenv

Run: pip install python-dotenv
2025-05-31 18:43:25 | CF-WATCHDOG | ERROR    | ‚ùå Missing dependencies: python-dotenv

Run: pip install python-dotenv
2025-05-31 18:44:32 | CF-WATCHDOG | ERROR    | ‚ùå Missing dependencies: python-dotenv

Run: pip install python-dotenv
2025-05-31 19:19:31 | CF-WATCHDOG | ERROR    | ‚ùå Missing dependencies: python-dotenv

Run: pip install python-dotenv
2025-05-31 19:19:31 | CF-WATCHDOG | INFO     | HTTP Request: POST https://api.telegram.org/bot7868571235:AAH8CMe_pAbDFLB41oj1fgS8uWCJffbjwDw/sendMessage "HTTP/1.1 200 OK"
2025-05-31 19:21:49 | CF-WATCHDOG | ERROR    | ‚ùå Missing dependencies: python-dotenv

Run: pip install python-dotenv
2025-05-31 19:21:49 | CF-WATCHDOG | INFO     | HTTP Request: POST https://api.telegram.org/bot7868571235:AAH8CMe_pAbDFLB41oj1fgS8uWCJffbjwDw/sendMessage "HTTP/1.1 200 OK"
2025-05-31 19:23:51 | CF-WATCHDOG | ERROR    | ‚ùå Missing dependencies: python-dotenv

Run: pip install python-dotenv
2025-05-31 19:23:51 | CF-WATCHDOG | INFO     | HTTP Request: POST https://api.telegram.org/bot7868571235:AAH8CMe_pAbDFLB41oj1fgS8uWCJffbjwDw/sendMessage "HTTP/1.1 200 OK"
2025-05-31 19:25:20 | CF-WATCHDOG | ERROR    | ‚ùå Missing dependencies: python-dotenv

Run: pip install python-dotenv
2025-05-31 19:25:20 | CF-WATCHDOG | INFO     | HTTP Request: POST https://api.telegram.org/bot7868571235:AAH8CMe_pAbDFLB41oj1fgS8uWCJffbjwDw/sendMessage "HTTP/1.1 200 OK"
2025-05-31 19:26:38 | CF-WATCHDOG | ERROR    | ‚ùå Missing dependencies: python-dotenv

Run: pip install python-dotenv
2025-05-31 19:26:38 | CF-WATCHDOG | INFO     | HTTP Request: POST https://api.telegram.org/bot7868571235:AAH8CMe_pAbDFLB41oj1fgS8uWCJffbjwDw/sendMessage "HTTP/1.1 200 OK"
2025-05-31 19:28:35 | CF-WATCHDOG | ERROR    | ‚ùå Missing dependencies: python-dotenv

Run: pip install python-dotenv
2025-05-31 19:28:35 | CF-WATCHDOG | INFO     | HTTP Request: POST https://api.telegram.org/bot7868571235:AAH8CMe_pAbDFLB41oj1fgS8uWCJffbjwDw/sendMessage "HTTP/1.1 200 OK"
2025-05-31 19:30:45 | CF-WATCHDOG | INFO     | HTTP Request: POST https://api.telegram.org/bot7868571235:AAH8CMe_pAbDFLB41oj1fgS8uWCJffbjwDw/sendMessage "HTTP/1.1 200 OK"
2025-05-31 19:30:45 | CF-WATCHDOG | INFO     | üöÄ Process started (PID: 472238)
2025-05-31 19:30:45 | CF-WATCHDOG | ERROR    | STDERR: Traceback (most recent call last):
2025-05-31 19:30:45 | CF-WATCHDOG | ERROR    | STDERR: File "/opt/coreflow/coreflow_main.py", line 12, in <module>
2025-05-31 19:30:45 | CF-WATCHDOG | ERROR    | STDERR: import redis
2025-05-31 19:30:45 | CF-WATCHDOG | ERROR    | STDERR: ModuleNotFoundError: No module named 'redis'
2025-05-31 19:30:55 | CF-WATCHDOG | WARNING  | ‚ö†Ô∏è Process stopped - attempting restart
2025-05-31 19:30:55 | CF-WATCHDOG | INFO     | üöÄ Process started (PID: 472250)
2025-05-31 19:30:55 | CF-WATCHDOG | ERROR    | STDERR: Traceback (most recent call last):
2025-05-31 19:30:55 | CF-WATCHDOG | ERROR    | STDERR: File "/opt/coreflow/coreflow_main.py", line 12, in <module>
2025-05-31 19:30:55 | CF-WATCHDOG | ERROR    | STDERR: import redis
2025-05-31 19:30:55 | CF-WATCHDOG | ERROR    | STDERR: ModuleNotFoundError: No module named 'redis'
2025-05-31 19:31:05 | CF-WATCHDOG | WARNING  | ‚ö†Ô∏è Process stopped - attempting restart
2025-05-31 19:31:05 | CF-WATCHDOG | INFO     | üöÄ Process started (PID: 472278)
2025-05-31 19:31:05 | CF-WATCHDOG | ERROR    | STDERR: Traceback (most recent call last):
2025-05-31 19:31:05 | CF-WATCHDOG | ERROR    | STDERR: File "/opt/coreflow/coreflow_main.py", line 12, in <module>
2025-05-31 19:31:05 | CF-WATCHDOG | ERROR    | STDERR: import redis
2025-05-31 19:31:05 | CF-WATCHDOG | ERROR    | STDERR: ModuleNotFoundError: No module named 'redis'
2025-05-31 19:31:15 | CF-WATCHDOG | WARNING  | ‚ö†Ô∏è Process stopped - attempting restart
2025-05-31 19:31:15 | CF-WATCHDOG | INFO     | üöÄ Process started (PID: 472289)
2025-05-31 19:31:15 | CF-WATCHDOG | ERROR    | STDERR: Traceback (most recent call last):
2025-05-31 19:31:15 | CF-WATCHDOG | ERROR    | STDERR: File "/opt/coreflow/coreflow_main.py", line 12, in <module>
2025-05-31 19:31:15 | CF-WATCHDOG | ERROR    | STDERR: import redis
2025-05-31 19:31:15 | CF-WATCHDOG | ERROR    | STDERR: ModuleNotFoundError: No module named 'redis'
2025-05-31 19:31:25 | CF-WATCHDOG | WARNING  | ‚ö†Ô∏è Process stopped - attempting restart
2025-05-31 19:31:25 | CF-WATCHDOG | INFO     | üöÄ Process started (PID: 472302)
2025-05-31 19:31:25 | CF-WATCHDOG | ERROR    | STDERR: Traceback (most recent call last):
2025-05-31 19:31:25 | CF-WATCHDOG | ERROR    | STDERR: File "/opt/coreflow/coreflow_main.py", line 12, in <module>
2025-05-31 19:31:25 | CF-WATCHDOG | ERROR    | STDERR: import redis
2025-05-31 19:31:25 | CF-WATCHDOG | ERROR    | STDERR: ModuleNotFoundError: No module named 'redis'
2025-05-31 19:31:35 | CF-WATCHDOG | WARNING  | ‚ö†Ô∏è Process stopped - attempting restart
2025-05-31 19:31:35 | CF-WATCHDOG | INFO     | üöÄ Process started (PID: 472329)
2025-05-31 19:31:35 | CF-WATCHDOG | ERROR    | STDERR: Traceback (most recent call last):
2025-05-31 19:31:35 | CF-WATCHDOG | ERROR    | STDERR: File "/opt/coreflow/coreflow_main.py", line 12, in <module>
2025-05-31 19:31:35 | CF-WATCHDOG | ERROR    | STDERR: import redis
2025-05-31 19:31:35 | CF-WATCHDOG | ERROR    | STDERR: ModuleNotFoundError: No module named 'redis'
2025-05-31 19:31:45 | CF-WATCHDOG | WARNING  | ‚ö†Ô∏è Process stopped - attempting restart
2025-05-31 19:31:45 | CF-WATCHDOG | INFO     | üîö Watchdog service stopped
2025-05-31 19:32:47 | CF-WATCHDOG | INFO     | HTTP Request: POST https://api.telegram.org/bot7868571235:AAH8CMe_pAbDFLB41oj1fgS8uWCJffbjwDw/sendMessage "HTTP/1.1 200 OK"
2025-05-31 19:32:47 | CF-WATCHDOG | INFO     | üöÄ Process started (PID: 472548)
2025-05-31 19:32:47 | CF-WATCHDOG | ERROR    | STDERR: Traceback (most recent call last):
2025-05-31 19:32:47 | CF-WATCHDOG | ERROR    | STDERR: File "/opt/coreflow/coreflow_main.py", line 17, in <module>
2025-05-31 19:32:47 | CF-WATCHDOG | ERROR    | STDERR: from core.strategy.valg_engine import FTMO_VALGEngine
2025-05-31 19:32:47 | CF-WATCHDOG | ERROR    | STDERR: File "/opt/coreflow/core/strategy/valg_engine.py", line 2, in <module>
2025-05-31 19:32:47 | CF-WATCHDOG | ERROR    | STDERR: import pandas as pd
2025-05-31 19:32:47 | CF-WATCHDOG | ERROR    | STDERR: ModuleNotFoundError: No module named 'pandas'
2025-05-31 19:32:57 | CF-WATCHDOG | WARNING  | ‚ö†Ô∏è Process stopped - attempting restart
2025-05-31 19:32:57 | CF-WATCHDOG | INFO     | üöÄ Process started (PID: 472588)
2025-05-31 19:32:57 | CF-WATCHDOG | ERROR    | STDERR: Traceback (most recent call last):
2025-05-31 19:32:57 | CF-WATCHDOG | ERROR    | STDERR: File "/opt/coreflow/coreflow_main.py", line 17, in <module>
2025-05-31 19:32:57 | CF-WATCHDOG | ERROR    | STDERR: from core.strategy.valg_engine import FTMO_VALGEngine
2025-05-31 19:32:57 | CF-WATCHDOG | ERROR    | STDERR: File "/opt/coreflow/core/strategy/valg_engine.py", line 2, in <module>
2025-05-31 19:32:57 | CF-WATCHDOG | ERROR    | STDERR: import pandas as pd
2025-05-31 19:32:57 | CF-WATCHDOG | ERROR    | STDERR: ModuleNotFoundError: No module named 'pandas'
2025-05-31 19:33:07 | CF-WATCHDOG | WARNING  | ‚ö†Ô∏è Process stopped - attempting restart
2025-05-31 19:33:07 | CF-WATCHDOG | INFO     | üöÄ Process started (PID: 472624)
2025-05-31 19:33:07 | CF-WATCHDOG | ERROR    | STDERR: Traceback (most recent call last):
2025-05-31 19:33:07 | CF-WATCHDOG | ERROR    | STDERR: File "/opt/coreflow/coreflow_main.py", line 17, in <module>
2025-05-31 19:33:07 | CF-WATCHDOG | ERROR    | STDERR: from core.strategy.valg_engine import FTMO_VALGEngine
2025-05-31 19:33:07 | CF-WATCHDOG | ERROR    | STDERR: File "/opt/coreflow/core/strategy/valg_engine.py", line 2, in <module>
2025-05-31 19:33:07 | CF-WATCHDOG | ERROR    | STDERR: import pandas as pd
2025-05-31 19:33:07 | CF-WATCHDOG | ERROR    | STDERR: ModuleNotFoundError: No module named 'pandas'
2025-05-31 19:33:17 | CF-WATCHDOG | WARNING  | ‚ö†Ô∏è Process stopped - attempting restart
2025-05-31 19:33:17 | CF-WATCHDOG | INFO     | üöÄ Process started (PID: 472654)
2025-05-31 19:33:17 | CF-WATCHDOG | ERROR    | STDERR: Traceback (most recent call last):
2025-05-31 19:33:17 | CF-WATCHDOG | ERROR    | STDERR: File "/opt/coreflow/coreflow_main.py", line 17, in <module>
2025-05-31 19:33:17 | CF-WATCHDOG | ERROR    | STDERR: from core.strategy.valg_engine import FTMO_VALGEngine
2025-05-31 19:33:17 | CF-WATCHDOG | ERROR    | STDERR: File "/opt/coreflow/core/strategy/valg_engine.py", line 2, in <module>
2025-05-31 19:33:17 | CF-WATCHDOG | ERROR    | STDERR: import pandas as pd
2025-05-31 19:33:17 | CF-WATCHDOG | ERROR    | STDERR: ModuleNotFoundError: No module named 'pandas'
2025-05-31 19:33:27 | CF-WATCHDOG | WARNING  | ‚ö†Ô∏è Process stopped - attempting restart
2025-05-31 19:33:27 | CF-WATCHDOG | INFO     | üöÄ Process started (PID: 472687)
2025-05-31 19:33:27 | CF-WATCHDOG | ERROR    | STDERR: Traceback (most recent call last):
2025-05-31 19:33:27 | CF-WATCHDOG | ERROR    | STDERR: File "/opt/coreflow/coreflow_main.py", line 17, in <module>
2025-05-31 19:33:27 | CF-WATCHDOG | ERROR    | STDERR: from core.strategy.valg_engine import FTMO_VALGEngine
2025-05-31 19:33:27 | CF-WATCHDOG | ERROR    | STDERR: File "/opt/coreflow/core/strategy/valg_engine.py", line 2, in <module>
2025-05-31 19:33:27 | CF-WATCHDOG | ERROR    | STDERR: import pandas as pd
2025-05-31 19:33:27 | CF-WATCHDOG | ERROR    | STDERR: ModuleNotFoundError: No module named 'pandas'
2025-05-31 19:33:27 | CF-WATCHDOG | INFO     | üõë Watchdog manually stopped
2025-05-31 19:33:27 | CF-WATCHDOG | INFO     | üîö Watchdog service stopped
2025-05-31 19:33:38 | CF-WATCHDOG | INFO     | HTTP Request: POST https://api.telegram.org/bot7868571235:AAH8CMe_pAbDFLB41oj1fgS8uWCJffbjwDw/sendMessage "HTTP/1.1 200 OK"
2025-05-31 19:33:38 | CF-WATCHDOG | INFO     | üöÄ Process started (PID: 472774)
2025-05-31 19:33:39 | CF-WATCHDOG | ERROR    | STDERR: Traceback (most recent call last):
2025-05-31 19:33:39 | CF-WATCHDOG | ERROR    | STDERR: File "/opt/coreflow/coreflow_main.py", line 18, in <module>
2025-05-31 19:33:39 | CF-WATCHDOG | ERROR    | STDERR: from core.market_data import MarketDataProvider
2025-05-31 19:33:39 | CF-WATCHDOG | ERROR    | STDERR: ModuleNotFoundError: No module named 'core.market_data'
2025-05-31 19:33:48 | CF-WATCHDOG | WARNING  | ‚ö†Ô∏è Process stopped - attempting restart
2025-05-31 19:33:48 | CF-WATCHDOG | INFO     | üöÄ Process started (PID: 472804)
2025-05-31 19:33:49 | CF-WATCHDOG | ERROR    | STDERR: Traceback (most recent call last):
2025-05-31 19:33:49 | CF-WATCHDOG | ERROR    | STDERR: File "/opt/coreflow/coreflow_main.py", line 18, in <module>
2025-05-31 19:33:49 | CF-WATCHDOG | ERROR    | STDERR: from core.market_data import MarketDataProvider
2025-05-31 19:33:49 | CF-WATCHDOG | ERROR    | STDERR: ModuleNotFoundError: No module named 'core.market_data'
2025-05-31 19:33:58 | CF-WATCHDOG | WARNING  | ‚ö†Ô∏è Process stopped - attempting restart
2025-05-31 19:33:58 | CF-WATCHDOG | INFO     | üöÄ Process started (PID: 472850)
2025-05-31 19:33:59 | CF-WATCHDOG | ERROR    | STDERR: Traceback (most recent call last):
2025-05-31 19:33:59 | CF-WATCHDOG | ERROR    | STDERR: File "/opt/coreflow/coreflow_main.py", line 18, in <module>
2025-05-31 19:33:59 | CF-WATCHDOG | ERROR    | STDERR: from core.market_data import MarketDataProvider
2025-05-31 19:33:59 | CF-WATCHDOG | ERROR    | STDERR: ModuleNotFoundError: No module named 'core.market_data'
2025-05-31 19:34:08 | CF-WATCHDOG | WARNING  | ‚ö†Ô∏è Process stopped - attempting restart
2025-05-31 19:34:08 | CF-WATCHDOG | INFO     | üöÄ Process started (PID: 472880)
2025-05-31 19:34:09 | CF-WATCHDOG | ERROR    | STDERR: Traceback (most recent call last):
2025-05-31 19:34:09 | CF-WATCHDOG | ERROR    | STDERR: File "/opt/coreflow/coreflow_main.py", line 18, in <module>
2025-05-31 19:34:09 | CF-WATCHDOG | ERROR    | STDERR: from core.market_data import MarketDataProvider
2025-05-31 19:34:09 | CF-WATCHDOG | ERROR    | STDERR: ModuleNotFoundError: No module named 'core.market_data'
2025-05-31 19:34:18 | CF-WATCHDOG | WARNING  | ‚ö†Ô∏è Process stopped - attempting restart
2025-05-31 19:34:18 | CF-WATCHDOG | INFO     | üöÄ Process started (PID: 472910)
2025-05-31 19:34:19 | CF-WATCHDOG | ERROR    | STDERR: Traceback (most recent call last):
2025-05-31 19:34:19 | CF-WATCHDOG | ERROR    | STDERR: File "/opt/coreflow/coreflow_main.py", line 18, in <module>
2025-05-31 19:34:19 | CF-WATCHDOG | ERROR    | STDERR: from core.market_data import MarketDataProvider
2025-05-31 19:34:19 | CF-WATCHDOG | ERROR    | STDERR: ModuleNotFoundError: No module named 'core.market_data'
2025-05-31 19:34:25 | CF-WATCHDOG | INFO     | üõë Watchdog manually stopped
2025-05-31 19:34:25 | CF-WATCHDOG | INFO     | üîö Watchdog service stopped
2025-05-31 20:17:44 | CF-WATCHDOG | INFO     | HTTP Request: POST https://api.telegram.org/bot7868571235:AAH8CMe_pAbDFLB41oj1fgS8uWCJffbjwDw/sendMessage "HTTP/1.1 200 OK"
2025-05-31 20:17:44 | CF-WATCHDOG | INFO     | üöÄ Process started (PID: 476756)
2025-05-31 20:17:44 | CF-WATCHDOG | ERROR    | STDERR: 2025-05-31 20:17:44,335 | CRITICAL | üîö FTMO initialization failed: HealthMonitor.__init__() got an unexpected keyword argument 'max_daily_trades'
2025-05-31 20:17:54 | CF-WATCHDOG | WARNING  | ‚ö†Ô∏è Process stopped - attempting restart
2025-05-31 20:17:54 | CF-WATCHDOG | INFO     | üöÄ Process started (PID: 476802)
2025-05-31 20:17:54 | CF-WATCHDOG | ERROR    | STDERR: 2025-05-31 20:17:54,348 | CRITICAL | üîö FTMO initialization failed: HealthMonitor.__init__() got an unexpected keyword argument 'max_daily_trades'
2025-05-31 20:18:04 | CF-WATCHDOG | WARNING  | ‚ö†Ô∏è Process stopped - attempting restart
2025-05-31 20:18:04 | CF-WATCHDOG | INFO     | üöÄ Process started (PID: 476832)
2025-05-31 20:18:04 | CF-WATCHDOG | ERROR    | STDERR: 2025-05-31 20:18:04,347 | CRITICAL | üîö FTMO initialization failed: HealthMonitor.__init__() got an unexpected keyword argument 'max_daily_trades'
2025-05-31 20:18:14 | CF-WATCHDOG | WARNING  | ‚ö†Ô∏è Process stopped - attempting restart
2025-05-31 20:18:14 | CF-WATCHDOG | INFO     | üöÄ Process started (PID: 476862)
2025-05-31 20:18:14 | CF-WATCHDOG | ERROR    | STDERR: 2025-05-31 20:18:14,348 | CRITICAL | üîö FTMO initialization failed: HealthMonitor.__init__() got an unexpected keyword argument 'max_daily_trades'
2025-05-31 20:18:24 | CF-WATCHDOG | WARNING  | ‚ö†Ô∏è Process stopped - attempting restart
2025-05-31 20:18:24 | CF-WATCHDOG | INFO     | üöÄ Process started (PID: 476908)
2025-05-31 20:18:24 | CF-WATCHDOG | ERROR    | STDERR: 2025-05-31 20:18:24,358 | CRITICAL | üîö FTMO initialization failed: HealthMonitor.__init__() got an unexpected keyword argument 'max_daily_trades'
2025-05-31 20:18:34 | CF-WATCHDOG | WARNING  | ‚ö†Ô∏è Process stopped - attempting restart
2025-05-31 20:18:34 | CF-WATCHDOG | INFO     | üöÄ Process started (PID: 476940)
2025-05-31 20:18:34 | CF-WATCHDOG | ERROR    | STDERR: 2025-05-31 20:18:34,368 | CRITICAL | üîö FTMO initialization failed: HealthMonitor.__init__() got an unexpected keyword argument 'max_daily_trades'
2025-05-31 20:18:44 | CF-WATCHDOG | WARNING  | ‚ö†Ô∏è Process stopped - attempting restart
2025-05-31 20:18:44 | CF-WATCHDOG | INFO     | üîö Watchdog service stopped
2025-05-31 20:40:12 | CF-WATCHDOG | INFO     | HTTP Request: POST https://api.telegram.org/bot7868571235:AAH8CMe_pAbDFLB41oj1fgS8uWCJffbjwDw/sendMessage "HTTP/1.1 200 OK"
2025-05-31 20:40:12 | CF-WATCHDOG | INFO     | üöÄ Process started (PID: 479083)
2025-05-31 20:40:12 | CF-WATCHDOG | ERROR    | STDERR: 2025-05-31 20:40:12,959 | INFO | üöÄ Starting Institutional Health Monitor
2025-05-31 20:40:12 | CF-WATCHDOG | ERROR    | STDERR: Traceback (most recent call last):
2025-05-31 20:40:12 | CF-WATCHDOG | ERROR    | STDERR: File "/opt/coreflow/coreflow_main.py", line 200, in <module>
2025-05-31 20:40:12 | CF-WATCHDOG | ERROR    | STDERR: main()
2025-05-31 20:40:12 | CF-WATCHDOG | ERROR    | STDERR: File "/opt/coreflow/coreflow_main.py", line 197, in main
2025-05-31 20:40:12 | CF-WATCHDOG | ERROR    | STDERR: main_loop()
2025-05-31 20:40:12 | CF-WATCHDOG | ERROR    | STDERR: File "/opt/coreflow/coreflow_main.py", line 148, in main_loop
2025-05-31 20:40:12 | CF-WATCHDOG | ERROR    | STDERR: 2025-05-31 20:40:12,959 | ERROR | Monitoring error: 'open'
2025-05-31 20:40:12 | CF-WATCHDOG | ERROR    | STDERR: Traceback (most recent call last):
2025-05-31 20:40:12 | CF-WATCHDOG | ERROR    | STDERR: File "/opt/coreflow/core/health_check.py", line 81, in _monitor_loop
2025-05-31 20:40:12 | CF-WATCHDOG | ERROR    | STDERR: self._check_trading_conditions()
2025-05-31 20:40:12 | CF-WATCHDOG | ERROR    | STDERR: File "/opt/coreflow/core/health_check.py", line 101, in _check_trading_conditions
2025-05-31 20:40:12 | CF-WATCHDOG | ERROR    | STDERR: if not self._is_market_open():
2025-05-31 20:40:12 | CF-WATCHDOG | ERROR    | STDERR: ^^^^^^^^^^^^^^^^^^^^^^
2025-05-31 20:40:12 | CF-WATCHDOG | ERROR    | STDERR: File "/opt/coreflow/core/health_check.py", line 127, in _is_market_open
2025-05-31 20:40:12 | CF-WATCHDOG | ERROR    | STDERR: if (current_time < market_hours['open'] or
2025-05-31 20:40:12 | CF-WATCHDOG | ERROR    | STDERR: ~~~~~~~~~~~~^^^^^^^^
2025-05-31 20:40:12 | CF-WATCHDOG | ERROR    | STDERR: KeyError: 'open'
2025-05-31 20:40:12 | CF-WATCHDOG | ERROR    | STDERR: engine = FTMO_VALGEngine(
2025-05-31 20:40:12 | CF-WATCHDOG | ERROR    | STDERR: ^^^^^^^^^^^^^^^^
2025-05-31 20:40:12 | CF-WATCHDOG | ERROR    | STDERR: TypeError: FTMO_VALGEngine.__init__() got an unexpected keyword argument 'min_spread'
2025-05-31 20:40:22 | CF-WATCHDOG | WARNING  | ‚ö†Ô∏è Process stopped - attempting restart
2025-05-31 20:40:22 | CF-WATCHDOG | INFO     | üöÄ Process started (PID: 479115)
2025-05-31 20:40:22 | CF-WATCHDOG | ERROR    | STDERR: 2025-05-31 20:40:22,965 | INFO | üöÄ Starting Institutional Health Monitor
2025-05-31 20:40:22 | CF-WATCHDOG | ERROR    | STDERR: Traceback (most recent call last):
2025-05-31 20:40:22 | CF-WATCHDOG | ERROR    | STDERR: File "/opt/coreflow/coreflow_main.py", line 200, in <module>
2025-05-31 20:40:22 | CF-WATCHDOG | ERROR    | STDERR: main()
2025-05-31 20:40:22 | CF-WATCHDOG | ERROR    | STDERR: File "/opt/coreflow/coreflow_main.py", line 197, in main
2025-05-31 20:40:22 | CF-WATCHDOG | ERROR    | STDERR: main_loop()
2025-05-31 20:40:22 | CF-WATCHDOG | ERROR    | STDERR: File "/opt/coreflow/coreflow_main.py", line 148, in main_loop
2025-05-31 20:40:22 | CF-WATCHDOG | ERROR    | STDERR: engine = FTMO_VALGEngine(
2025-05-31 20:40:22 | CF-WATCHDOG | ERROR    | STDERR: ^^^^^^^^^^^^^^^^
2025-05-31 20:40:22 | CF-WATCHDOG | ERROR    | STDERR: TypeError: FTMO_VALGEngine.__init__() got an unexpected keyword argument 'min_spread'
2025-05-31 20:40:22 | CF-WATCHDOG | ERROR    | STDERR: 2025-05-31 20:40:22,965 | ERROR | Monitoring error: 'open'
2025-05-31 20:40:22 | CF-WATCHDOG | ERROR    | STDERR: Traceback (most recent call last):
2025-05-31 20:40:22 | CF-WATCHDOG | ERROR    | STDERR: File "/opt/coreflow/core/health_check.py", line 81, in _monitor_loop
2025-05-31 20:40:22 | CF-WATCHDOG | ERROR    | STDERR: self._check_trading_conditions()
2025-05-31 20:40:22 | CF-WATCHDOG | ERROR    | STDERR: File "/opt/coreflow/core/health_check.py", line 101, in _check_trading_conditions
2025-05-31 20:40:22 | CF-WATCHDOG | ERROR    | STDERR: if not self._is_market_open():
2025-05-31 20:40:22 | CF-WATCHDOG | ERROR    | STDERR: ^^^^^^^^^^^^^^^^^^^^^^
2025-05-31 20:40:22 | CF-WATCHDOG | ERROR    | STDERR: File "/opt/coreflow/core/health_check.py", line 127, in _is_market_open
2025-05-31 20:40:22 | CF-WATCHDOG | ERROR    | STDERR: if (current_time < market_hours['open'] or
2025-05-31 20:40:22 | CF-WATCHDOG | ERROR    | STDERR: ~~~~~~~~~~~~^^^^^^^^
2025-05-31 20:40:22 | CF-WATCHDOG | ERROR    | STDERR: KeyError: 'open'
2025-05-31 20:40:32 | CF-WATCHDOG | WARNING  | ‚ö†Ô∏è Process stopped - attempting restart
2025-05-31 20:40:32 | CF-WATCHDOG | INFO     | üöÄ Process started (PID: 479164)
2025-05-31 20:40:32 | CF-WATCHDOG | ERROR    | STDERR: 2025-05-31 20:40:32,969 | INFO | üöÄ Starting Institutional Health Monitor
2025-05-31 20:40:32 | CF-WATCHDOG | ERROR    | STDERR: 2025-05-31 20:40:32,969 | ERROR | Monitoring error: 'open'
2025-05-31 20:40:32 | CF-WATCHDOG | ERROR    | STDERR: Traceback (most recent call last):
2025-05-31 20:40:32 | CF-WATCHDOG | ERROR    | STDERR: File "/opt/coreflow/core/health_check.py", line 81, in _monitor_loop
2025-05-31 20:40:32 | CF-WATCHDOG | ERROR    | STDERR: self._check_trading_conditions()
2025-05-31 20:40:32 | CF-WATCHDOG | ERROR    | STDERR: File "/opt/coreflow/core/health_check.py", line 101, in _check_trading_conditions
2025-05-31 20:40:32 | CF-WATCHDOG | ERROR    | STDERR: if not self._is_market_open():
2025-05-31 20:40:32 | CF-WATCHDOG | ERROR    | STDERR: ^^^^^^^^^^^^^^^^^^^^^^
2025-05-31 20:40:32 | CF-WATCHDOG | ERROR    | STDERR: File "/opt/coreflow/core/health_check.py", line 127, in _is_market_open
2025-05-31 20:40:32 | CF-WATCHDOG | ERROR    | STDERR: if (current_time < market_hours['open'] or
2025-05-31 20:40:32 | CF-WATCHDOG | ERROR    | STDERR: ~~~~~~~~~~~~^^^^^^^^
2025-05-31 20:40:32 | CF-WATCHDOG | ERROR    | STDERR: KeyError: 'open'
2025-05-31 20:40:32 | CF-WATCHDOG | ERROR    | STDERR: Traceback (most recent call last):
2025-05-31 20:40:32 | CF-WATCHDOG | ERROR    | STDERR: File "/opt/coreflow/coreflow_main.py", line 200, in <module>
2025-05-31 20:40:32 | CF-WATCHDOG | ERROR    | STDERR: main()
2025-05-31 20:40:32 | CF-WATCHDOG | ERROR    | STDERR: File "/opt/coreflow/coreflow_main.py", line 197, in main
2025-05-31 20:40:32 | CF-WATCHDOG | ERROR    | STDERR: main_loop()
2025-05-31 20:40:32 | CF-WATCHDOG | ERROR    | STDERR: File "/opt/coreflow/coreflow_main.py", line 148, in main_loop
2025-05-31 20:40:32 | CF-WATCHDOG | ERROR    | STDERR: engine = FTMO_VALGEngine(
2025-05-31 20:40:32 | CF-WATCHDOG | ERROR    | STDERR: ^^^^^^^^^^^^^^^^
2025-05-31 20:40:32 | CF-WATCHDOG | ERROR    | STDERR: TypeError: FTMO_VALGEngine.__init__() got an unexpected keyword argument 'min_spread'
2025-05-31 20:40:42 | CF-WATCHDOG | INFO     | üõë Watchdog manually stopped
2025-05-31 20:40:42 | CF-WATCHDOG | INFO     | üîö Watchdog service stopped
2025-05-31 21:13:46 CF.InstitutionalWatchdog ERROR    Missing dependencies: python-dotenv
2025-05-31 21:13:46 httpx                INFO     HTTP Request: POST https://api.telegram.org/bot7868571235:AAH8CMe_pAbDFLB41oj1fgS8uWCJffbjwDw/sendMessage "HTTP/1.1 200 OK"
2025-05-31 21:26:13 - CF.Watchdog - ERROR - Missing packages: python-dotenv
2025-05-31 21:28:00 - CF.Watchdog - ERROR - Missing packages: python-dotenv
2025-05-31 21:30:13 - CF.Watchdog - ERROR - Missing packages: python-dotenv
2025-05-31 21:40:01 - CF.Watchdog - ERROR - Missing packages: python-dotenv
2025-05-31 21:40:48 - CF.Watchdog - ERROR - Missing packages: python-dotenv
2025-05-31 21:41:19 - CF.Watchdog - ERROR - Missing packages: python-dotenv
2025-05-31 21:42:48 - CF.Watchdog - ERROR - Missing packages: python-dotenv
2025-05-31 21:43:25 - CF.Watchdog - ERROR - Missing packages: python-dotenv
2025-05-31 21:44:22 - CF.Watchdog - ERROR - Process launch failed: name 'threading' is not defined
2025-05-31 21:44:32 - CF.Watchdog - ERROR - Process launch failed: name 'threading' is not defined
2025-05-31 21:51:57,922 INFO     Started: PID 490265
2025-05-31 21:51:57,950 ERROR    Traceback (most recent call last):
2025-05-31 21:51:57,950 ERROR    File "/opt/coreflow/coreflow_main.py", line 17, in <module>
2025-05-31 21:51:57,950 ERROR    import pandas as pd
2025-05-31 21:51:57,950 ERROR    ModuleNotFoundError: No module named 'pandas'
2025-05-31 21:51:59,059 WARNING  Process stopped.
2025-05-31 21:51:59,195 INFO     Started: PID 490270
2025-05-31 21:51:59,222 ERROR    Traceback (most recent call last):
2025-05-31 21:51:59,222 ERROR    File "/opt/coreflow/coreflow_main.py", line 17, in <module>
2025-05-31 21:51:59,222 ERROR    import pandas as pd
2025-05-31 21:51:59,222 ERROR    ModuleNotFoundError: No module named 'pandas'
2025-05-31 21:52:05,338 WARNING  Process stopped.
2025-05-31 21:52:05,513 INFO     Started: PID 490280
2025-05-31 21:52:05,537 ERROR    Traceback (most recent call last):
2025-05-31 21:52:05,537 ERROR    File "/opt/coreflow/coreflow_main.py", line 17, in <module>
2025-05-31 21:52:05,537 ERROR    import pandas as pd
2025-05-31 21:52:05,537 ERROR    ModuleNotFoundError: No module named 'pandas'
2025-05-31 21:52:11,713 WARNING  Process stopped.
2025-05-31 21:52:11,716 INFO     Watchdog terminated.
2025-05-31 21:53:02,129 INFO     Started: PID 490439
2025-05-31 21:53:02,312 ERROR    Traceback (most recent call last):
2025-05-31 21:53:02,313 ERROR    File "/opt/coreflow/coreflow_main.py", line 20, in <module>
2025-05-31 21:53:02,313 ERROR    from core.health_check import HealthMonitor
2025-05-31 21:53:02,313 ERROR    File "/opt/coreflow/core/health_check.py", line 13, in <module>
2025-05-31 21:53:02,313 ERROR    import holidays
2025-05-31 21:53:02,313 ERROR    ModuleNotFoundError: No module named 'holidays'
2025-05-31 21:53:03,231 WARNING  Process stopped.
2025-05-31 21:53:03,305 INFO     Started: PID 490462
2025-05-31 21:53:03,492 ERROR    Traceback (most recent call last):
2025-05-31 21:53:03,492 ERROR    File "/opt/coreflow/coreflow_main.py", line 20, in <module>
2025-05-31 21:53:03,492 ERROR    from core.health_check import HealthMonitor
2025-05-31 21:53:03,492 ERROR    File "/opt/coreflow/core/health_check.py", line 13, in <module>
2025-05-31 21:53:03,492 ERROR    import holidays
2025-05-31 21:53:03,492 ERROR    ModuleNotFoundError: No module named 'holidays'
2025-05-31 21:53:09,375 WARNING  Process stopped.
2025-05-31 21:53:09,455 INFO     Started: PID 490506
2025-05-31 21:53:09,661 ERROR    Traceback (most recent call last):
2025-05-31 21:53:09,661 ERROR    File "/opt/coreflow/coreflow_main.py", line 20, in <module>
2025-05-31 21:53:09,661 ERROR    from core.health_check import HealthMonitor
2025-05-31 21:53:09,661 ERROR    File "/opt/coreflow/core/health_check.py", line 13, in <module>
2025-05-31 21:53:09,661 ERROR    import holidays
2025-05-31 21:53:09,661 ERROR    ModuleNotFoundError: No module named 'holidays'
2025-05-31 21:53:15,581 WARNING  Process stopped.
2025-05-31 21:53:15,650 INFO     Started: PID 490536
2025-05-31 21:53:15,837 ERROR    Traceback (most recent call last):
2025-05-31 21:53:15,837 ERROR    File "/opt/coreflow/coreflow_main.py", line 20, in <module>
2025-05-31 21:53:15,837 ERROR    from core.health_check import HealthMonitor
2025-05-31 21:53:15,837 ERROR    File "/opt/coreflow/core/health_check.py", line 13, in <module>
2025-05-31 21:53:15,838 ERROR    import holidays
2025-05-31 21:53:15,838 ERROR    ModuleNotFoundError: No module named 'holidays'
2025-05-31 21:53:21,727 WARNING  Process stopped.
2025-05-31 21:53:21,785 WARNING  Restart limit reached. Cooling down 600s.
2025-05-31 21:55:16,291 INFO     Watchdog terminated.
2025-05-31 21:55:45,622 INFO     Started: PID 490878
2025-05-31 21:55:45,818 ERROR    Traceback (most recent call last):
2025-05-31 21:55:45,818 ERROR    File "/opt/coreflow/coreflow_main.py", line 21, in <module>
2025-05-31 21:55:45,818 ERROR    from utils.telegram_notifier import send_telegram_alert
2025-05-31 21:55:45,818 ERROR    File "/opt/coreflow/utils/telegram_notifier.py", line 9, in <module>
2025-05-31 21:55:45,818 ERROR    import requests
2025-05-31 21:55:45,818 ERROR    ModuleNotFoundError: No module named 'requests'
2025-05-31 21:55:46,722 WARNING  Process stopped.
2025-05-31 21:55:46,784 INFO     Started: PID 490901
2025-05-31 21:55:46,982 ERROR    Traceback (most recent call last):
2025-05-31 21:55:46,982 ERROR    File "/opt/coreflow/coreflow_main.py", line 21, in <module>
2025-05-31 21:55:46,982 ERROR    from utils.telegram_notifier import send_telegram_alert
2025-05-31 21:55:46,982 ERROR    File "/opt/coreflow/utils/telegram_notifier.py", line 9, in <module>
2025-05-31 21:55:46,982 ERROR    import requests
2025-05-31 21:55:46,982 ERROR    ModuleNotFoundError: No module named 'requests'
2025-05-31 21:55:52,851 WARNING  Process stopped.
2025-05-31 21:55:52,917 INFO     Started: PID 490929
2025-05-31 21:55:53,104 ERROR    Traceback (most recent call last):
2025-05-31 21:55:53,104 ERROR    File "/opt/coreflow/coreflow_main.py", line 21, in <module>
2025-05-31 21:55:53,104 ERROR    from utils.telegram_notifier import send_telegram_alert
2025-05-31 21:55:53,104 ERROR    File "/opt/coreflow/utils/telegram_notifier.py", line 9, in <module>
2025-05-31 21:55:53,104 ERROR    import requests
2025-05-31 21:55:53,104 ERROR    ModuleNotFoundError: No module named 'requests'
2025-05-31 21:55:58,981 WARNING  Process stopped.
2025-05-31 21:55:59,041 INFO     Started: PID 490960
2025-05-31 21:55:59,231 ERROR    Traceback (most recent call last):
2025-05-31 21:55:59,232 ERROR    File "/opt/coreflow/coreflow_main.py", line 21, in <module>
2025-05-31 21:55:59,232 ERROR    from utils.telegram_notifier import send_telegram_alert
2025-05-31 21:55:59,232 ERROR    File "/opt/coreflow/utils/telegram_notifier.py", line 9, in <module>
2025-05-31 21:55:59,232 ERROR    import requests
2025-05-31 21:55:59,232 ERROR    ModuleNotFoundError: No module named 'requests'
2025-05-31 21:56:02,925 INFO     Watchdog terminated.
2025-05-31 21:57:15,540 INFO     Started: PID 491186
2025-05-31 21:57:15,816 ERROR    2025-05-31 21:57:15,815 | INFO | üöÄ Starting Institutional Health Monitor
2025-05-31 21:57:15,816 ERROR    2025-05-31 21:57:15,815 | INFO | üöÄ Starting Institutional Health Monitor
2025-05-31 21:57:15,816 ERROR    2025-05-31 21:57:15,816 | ERROR | ‚ùå Trading hours for 'forex' not defined properly.
2025-05-31 21:57:15,816 ERROR    2025-05-31 21:57:15,816 | ERROR | ‚ùå Trading hours for 'forex' not defined properly.
2025-05-31 21:57:15,816 ERROR    2025-05-31 21:57:15,816 | WARNING | üö® Institutional Violation: Outside institutional trading hours
2025-05-31 21:57:15,816 ERROR    2025-05-31 21:57:15,816 | WARNING | üö® Institutional Violation: Outside institutional trading hours
2025-05-31 21:57:15,816 ERROR    Traceback (most recent call last):
2025-05-31 21:57:15,816 ERROR    File "/opt/coreflow/coreflow_main.py", line 200, in <module>
2025-05-31 21:57:15,816 ERROR    main()
2025-05-31 21:57:15,816 ERROR    File "/opt/coreflow/coreflow_main.py", line 197, in main
2025-05-31 21:57:15,816 ERROR    main_loop()
2025-05-31 21:57:15,816 ERROR    File "/opt/coreflow/coreflow_main.py", line 148, in main_loop
2025-05-31 21:57:15,816 ERROR    engine = FTMO_VALGEngine(
2025-05-31 21:57:15,816 ERROR    ^^^^^^^^^^^^^^^^
2025-05-31 21:57:15,816 ERROR    TypeError: FTMO_VALGEngine.__init__() got an unexpected keyword argument 'min_spread'
2025-05-31 21:57:16,731 WARNING  Process stopped.
2025-05-31 21:57:16,798 INFO     Started: PID 491213
2025-05-31 21:57:17,058 ERROR    2025-05-31 21:57:17,058 | INFO | üöÄ Starting Institutional Health Monitor
2025-05-31 21:57:17,058 ERROR    2025-05-31 21:57:17,058 | INFO | üöÄ Starting Institutional Health Monitor
2025-05-31 21:57:17,059 ERROR    2025-05-31 21:57:17,059 | ERROR | ‚ùå Trading hours for 'forex' not defined properly.
2025-05-31 21:57:17,059 ERROR    2025-05-31 21:57:17,059 | ERROR | ‚ùå Trading hours for 'forex' not defined properly.
2025-05-31 21:57:17,059 ERROR    2025-05-31 21:57:17,059 | WARNING | üö® Institutional Violation: Outside institutional trading hours
2025-05-31 21:57:17,059 ERROR    2025-05-31 21:57:17,059 | WARNING | üö® Institutional Violation: Outside institutional trading hours
2025-05-31 21:57:17,059 ERROR    Traceback (most recent call last):
2025-05-31 21:57:17,059 ERROR    File "/opt/coreflow/coreflow_main.py", line 200, in <module>
2025-05-31 21:57:17,059 ERROR    main()
2025-05-31 21:57:17,059 ERROR    File "/opt/coreflow/coreflow_main.py", line 197, in main
2025-05-31 21:57:17,059 ERROR    main_loop()
2025-05-31 21:57:17,059 ERROR    File "/opt/coreflow/coreflow_main.py", line 148, in main_loop
2025-05-31 21:57:17,059 ERROR    engine = FTMO_VALGEngine(
2025-05-31 21:57:17,059 ERROR    ^^^^^^^^^^^^^^^^
2025-05-31 21:57:17,059 ERROR    TypeError: FTMO_VALGEngine.__init__() got an unexpected keyword argument 'min_spread'
2025-05-31 21:57:22,860 WARNING  Process stopped.
2025-05-31 21:57:22,924 INFO     Started: PID 491242
2025-05-31 21:57:23,193 ERROR    2025-05-31 21:57:23,193 | INFO | üöÄ Starting Institutional Health Monitor
2025-05-31 21:57:23,193 ERROR    2025-05-31 21:57:23,193 | INFO | üöÄ Starting Institutional Health Monitor
2025-05-31 21:57:23,194 ERROR    2025-05-31 21:57:23,193 | ERROR | ‚ùå Trading hours for 'forex' not defined properly.
2025-05-31 21:57:23,194 ERROR    Traceback (most recent call last):
2025-05-31 21:57:23,194 ERROR    File "/opt/coreflow/coreflow_main.py", line 200, in <module>
2025-05-31 21:57:23,194 ERROR    2025-05-31 21:57:23,193 | ERROR | ‚ùå Trading hours for 'forex' not defined properly.
2025-05-31 21:57:23,194 ERROR    2025-05-31 21:57:23,194 | WARNING | üö® Institutional Violation: Outside institutional trading hours
2025-05-31 21:57:23,194 ERROR    2025-05-31 21:57:23,194 | WARNING | üö® Institutional Violation: Outside institutional trading hours
2025-05-31 21:57:23,194 ERROR    main()
2025-05-31 21:57:23,194 ERROR    File "/opt/coreflow/coreflow_main.py", line 197, in main
2025-05-31 21:57:23,194 ERROR    main_loop()
2025-05-31 21:57:23,194 ERROR    File "/opt/coreflow/coreflow_main.py", line 148, in main_loop
2025-05-31 21:57:23,194 ERROR    engine = FTMO_VALGEngine(
2025-05-31 21:57:23,194 ERROR    ^^^^^^^^^^^^^^^^
2025-05-31 21:57:23,194 ERROR    TypeError: FTMO_VALGEngine.__init__() got an unexpected keyword argument 'min_spread'
2025-05-31 21:57:28,998 WARNING  Process stopped.
2025-05-31 21:57:29,057 INFO     Started: PID 491276
2025-05-31 21:57:29,325 ERROR    2025-05-31 21:57:29,325 | INFO | üöÄ Starting Institutional Health Monitor
2025-05-31 21:57:29,325 ERROR    2025-05-31 21:57:29,325 | INFO | üöÄ Starting Institutional Health Monitor
2025-05-31 21:57:29,325 ERROR    2025-05-31 21:57:29,325 | ERROR | ‚ùå Trading hours for 'forex' not defined properly.
2025-05-31 21:57:29,325 ERROR    2025-05-31 21:57:29,325 | ERROR | ‚ùå Trading hours for 'forex' not defined properly.
2025-05-31 21:57:29,325 ERROR    2025-05-31 21:57:29,325 | WARNING | üö® Institutional Violation: Outside institutional trading hours
2025-05-31 21:57:29,325 ERROR    Traceback (most recent call last):
2025-05-31 21:57:29,325 ERROR    File "/opt/coreflow/coreflow_main.py", line 200, in <module>
2025-05-31 21:57:29,326 ERROR    main()
2025-05-31 21:57:29,326 ERROR    File "/opt/coreflow/coreflow_main.py", line 197, in main
2025-05-31 21:57:29,326 ERROR    2025-05-31 21:57:29,325 | WARNING | üö® Institutional Violation: Outside institutional trading hours
2025-05-31 21:57:29,326 ERROR    main_loop()
2025-05-31 21:57:29,326 ERROR    File "/opt/coreflow/coreflow_main.py", line 148, in main_loop
2025-05-31 21:57:29,326 ERROR    engine = FTMO_VALGEngine(
2025-05-31 21:57:29,326 ERROR    ^^^^^^^^^^^^^^^^
2025-05-31 21:57:29,326 ERROR    TypeError: FTMO_VALGEngine.__init__() got an unexpected keyword argument 'min_spread'
2025-05-31 21:57:31,553 INFO     Watchdog terminated.
2025-05-31 21:58:36,959 INFO     Started: PID 491492
2025-05-31 21:58:37,218 ERROR    2025-05-31 21:58:37,218 | INFO | üöÄ Starting Institutional Health Monitor
2025-05-31 21:58:37,218 ERROR    2025-05-31 21:58:37,218 | INFO | üöÄ Starting Institutional Health Monitor
2025-05-31 21:58:37,219 ERROR    2025-05-31 21:58:37,218 | ERROR | ‚ùå Trading hours for 'forex' not defined properly.
2025-05-31 21:58:37,219 ERROR    Traceback (most recent call last):
2025-05-31 21:58:37,219 ERROR    File "/opt/coreflow/coreflow_main.py", line 200, in <module>
2025-05-31 21:58:37,219 ERROR    2025-05-31 21:58:37,218 | ERROR | ‚ùå Trading hours for 'forex' not defined properly.
2025-05-31 21:58:37,219 ERROR    2025-05-31 21:58:37,219 | WARNING | üö® Institutional Violation: Outside institutional trading hours
2025-05-31 21:58:37,219 ERROR    2025-05-31 21:58:37,219 | WARNING | üö® Institutional Violation: Outside institutional trading hours
2025-05-31 21:58:37,219 ERROR    main()
2025-05-31 21:58:37,219 ERROR    File "/opt/coreflow/coreflow_main.py", line 197, in main
2025-05-31 21:58:37,219 ERROR    main_loop()
2025-05-31 21:58:37,219 ERROR    File "/opt/coreflow/coreflow_main.py", line 148, in main_loop
2025-05-31 21:58:37,219 ERROR    engine = FTMO_VALGEngine(
2025-05-31 21:58:37,219 ERROR    ^^^^^^^^^^^^^^^^
2025-05-31 21:58:37,219 ERROR    TypeError: FTMO_VALGEngine.__init__() got an unexpected keyword argument 'min_spread'
2025-05-31 21:58:38,119 WARNING  Process stopped.
2025-05-31 21:58:38,184 INFO     Started: PID 491516
2025-05-31 21:58:38,444 ERROR    2025-05-31 21:58:38,444 | INFO | üöÄ Starting Institutional Health Monitor
2025-05-31 21:58:38,444 ERROR    2025-05-31 21:58:38,444 | INFO | üöÄ Starting Institutional Health Monitor
2025-05-31 21:58:38,445 ERROR    2025-05-31 21:58:38,445 | ERROR | ‚ùå Trading hours for 'forex' not defined properly.
2025-05-31 21:58:38,445 ERROR    Traceback (most recent call last):
2025-05-31 21:58:38,445 ERROR    File "/opt/coreflow/coreflow_main.py", line 200, in <module>
2025-05-31 21:58:38,445 ERROR    2025-05-31 21:58:38,445 | ERROR | ‚ùå Trading hours for 'forex' not defined properly.
2025-05-31 21:58:38,445 ERROR    2025-05-31 21:58:38,445 | WARNING | üö® Institutional Violation: Outside institutional trading hours
2025-05-31 21:58:38,445 ERROR    2025-05-31 21:58:38,445 | WARNING | üö® Institutional Violation: Outside institutional trading hours
2025-05-31 21:58:38,445 ERROR    main()
2025-05-31 21:58:38,445 ERROR    File "/opt/coreflow/coreflow_main.py", line 197, in main
2025-05-31 21:58:38,445 ERROR    main_loop()
2025-05-31 21:58:38,445 ERROR    File "/opt/coreflow/coreflow_main.py", line 148, in main_loop
2025-05-31 21:58:38,445 ERROR    engine = FTMO_VALGEngine(
2025-05-31 21:58:38,445 ERROR    ^^^^^^^^^^^^^^^^
2025-05-31 21:58:38,445 ERROR    TypeError: FTMO_VALGEngine.__init__() got an unexpected keyword argument 'min_spread'
2025-05-31 21:58:44,250 WARNING  Process stopped.
2025-05-31 21:58:44,330 INFO     Started: PID 491561
2025-05-31 21:58:44,586 ERROR    2025-05-31 21:58:44,586 | INFO | üöÄ Starting Institutional Health Monitor
2025-05-31 21:58:44,586 ERROR    2025-05-31 21:58:44,586 | INFO | üöÄ Starting Institutional Health Monitor
2025-05-31 21:58:44,586 ERROR    2025-05-31 21:58:44,586 | ERROR | ‚ùå Trading hours for 'forex' not defined properly.
2025-05-31 21:58:44,586 ERROR    2025-05-31 21:58:44,586 | ERROR | ‚ùå Trading hours for 'forex' not defined properly.
2025-05-31 21:58:44,587 ERROR    2025-05-31 21:58:44,586 | WARNING | üö® Institutional Violation: Outside institutional trading hours
2025-05-31 21:58:44,587 ERROR    Traceback (most recent call last):
2025-05-31 21:58:44,587 ERROR    File "/opt/coreflow/coreflow_main.py", line 200, in <module>
2025-05-31 21:58:44,587 ERROR    2025-05-31 21:58:44,586 | WARNING | üö® Institutional Violation: Outside institutional trading hours
2025-05-31 21:58:44,587 ERROR    main()
2025-05-31 21:58:44,587 ERROR    File "/opt/coreflow/coreflow_main.py", line 197, in main
2025-05-31 21:58:44,587 ERROR    main_loop()
2025-05-31 21:58:44,587 ERROR    File "/opt/coreflow/coreflow_main.py", line 148, in main_loop
2025-05-31 21:58:44,587 ERROR    engine = FTMO_VALGEngine(
2025-05-31 21:58:44,587 ERROR    ^^^^^^^^^^^^^^^^
2025-05-31 21:58:44,587 ERROR    TypeError: FTMO_VALGEngine.__init__() got an unexpected keyword argument 'min_spread'
2025-05-31 21:58:48,886 INFO     Watchdog terminated.
2025-05-31 22:05:42,685 INFO     Started: PID 492558
2025-05-31 22:05:42,882 ERROR    2025-05-31 22:05:42,882 | INFO | üß† Starting CoreFlow Institutional Trading System
2025-05-31 22:05:42,915 ERROR    2025-05-31 22:05:42,915 | INFO | üöÄ Starting Institutional Health Monitor
2025-05-31 22:05:42,915 ERROR    2025-05-31 22:05:42,915 | INFO | üöÄ Starting Institutional Health Monitor
2025-05-31 22:05:42,916 ERROR    2025-05-31 22:05:42,916 | ERROR | Unexpected error: [Errno 2] No such file or directory: 'market_data.csv'
2025-05-31 22:05:42,916 ERROR    Traceback (most recent call last):
2025-05-31 22:05:42,917 ERROR    File "/opt/coreflow/coreflow_main.py", line 89, in main_loop
2025-05-31 22:05:42,917 ERROR    df = pd.read_csv("market_data.csv")  # Simulation / Testdaten
2025-05-31 22:05:42,917 ERROR    ^^^^^^^^^^^^^^^^^^^^^^^^^^^^^^
2025-05-31 22:05:42,917 ERROR    File "/opt/coreflow/.venv/lib/python3.12/site-packages/pandas/io/parsers/readers.py", line 1026, in read_csv
2025-05-31 22:05:42,917 ERROR    return _read(filepath_or_buffer, kwds)
2025-05-31 22:05:42,917 ERROR    ^^^^^^^^^^^^^^^^^^^^^^^^^^^^^^^
2025-05-31 22:05:42,917 ERROR    File "/opt/coreflow/.venv/lib/python3.12/site-packages/pandas/io/parsers/readers.py", line 620, in _read
2025-05-31 22:05:42,917 ERROR    parser = TextFileReader(filepath_or_buffer, **kwds)
2025-05-31 22:05:42,917 ERROR    ^^^^^^^^^^^^^^^^^^^^^^^^^^^^^^^^^^^^^^^^^^
2025-05-31 22:05:42,917 ERROR    File "/opt/coreflow/.venv/lib/python3.12/site-packages/pandas/io/parsers/readers.py", line 1620, in __init__
2025-05-31 22:05:42,917 ERROR    self._engine = self._make_engine(f, self.engine)
2025-05-31 22:05:42,917 ERROR    ^^^^^^^^^^^^^^^^^^^^^^^^^^^^^^^^^
2025-05-31 22:05:42,917 ERROR    File "/opt/coreflow/.venv/lib/python3.12/site-packages/pandas/io/parsers/readers.py", line 1880, in _make_engine
2025-05-31 22:05:42,917 ERROR    self.handles = get_handle(
2025-05-31 22:05:42,917 ERROR    ^^^^^^^^^^^
2025-05-31 22:05:42,917 ERROR    File "/opt/coreflow/.venv/lib/python3.12/site-packages/pandas/io/common.py", line 873, in get_handle
2025-05-31 22:05:42,917 ERROR    handle = open(
2025-05-31 22:05:42,917 ERROR    ^^^^^
2025-05-31 22:05:42,917 ERROR    FileNotFoundError: [Errno 2] No such file or directory: 'market_data.csv'
2025-05-31 22:05:42,917 ERROR    
2025-05-31 22:05:47,036 INFO     Watchdog terminated.
2025-05-31 22:07:55,597 INFO     Started: PID 492825
2025-05-31 22:07:55,803 ERROR    2025-05-31 22:07:55,803 | INFO | üß† Starting CoreFlow Institutional Trading System
2025-05-31 22:07:55,835 ERROR    2025-05-31 22:07:55,835 | INFO | üöÄ Starting Institutional Health Monitor
2025-05-31 22:07:55,835 ERROR    2025-05-31 22:07:55,835 | INFO | üöÄ Starting Institutional Health Monitor
2025-05-31 22:07:55,836 ERROR    2025-05-31 22:07:55,836 | ERROR | Unexpected error: [Errno 2] No such file or directory: 'market_data.csv'
2025-05-31 22:07:55,836 ERROR    Traceback (most recent call last):
2025-05-31 22:07:55,836 ERROR    File "/opt/coreflow/coreflow_main.py", line 89, in main_loop
2025-05-31 22:07:55,836 ERROR    df = pd.read_csv("market_data.csv")  # Simulation / Testdaten
2025-05-31 22:07:55,836 ERROR    ^^^^^^^^^^^^^^^^^^^^^^^^^^^^^^
2025-05-31 22:07:55,837 ERROR    File "/opt/coreflow/.venv/lib/python3.12/site-packages/pandas/io/parsers/readers.py", line 1026, in read_csv
2025-05-31 22:07:55,837 ERROR    return _read(filepath_or_buffer, kwds)
2025-05-31 22:07:55,837 ERROR    ^^^^^^^^^^^^^^^^^^^^^^^^^^^^^^^
2025-05-31 22:07:55,837 ERROR    File "/opt/coreflow/.venv/lib/python3.12/site-packages/pandas/io/parsers/readers.py", line 620, in _read
2025-05-31 22:07:55,837 ERROR    parser = TextFileReader(filepath_or_buffer, **kwds)
2025-05-31 22:07:55,837 ERROR    ^^^^^^^^^^^^^^^^^^^^^^^^^^^^^^^^^^^^^^^^^^
2025-05-31 22:07:55,837 ERROR    File "/opt/coreflow/.venv/lib/python3.12/site-packages/pandas/io/parsers/readers.py", line 1620, in __init__
2025-05-31 22:07:55,837 ERROR    self._engine = self._make_engine(f, self.engine)
2025-05-31 22:07:55,837 ERROR    ^^^^^^^^^^^^^^^^^^^^^^^^^^^^^^^^^
2025-05-31 22:07:55,837 ERROR    File "/opt/coreflow/.venv/lib/python3.12/site-packages/pandas/io/parsers/readers.py", line 1880, in _make_engine
2025-05-31 22:07:55,837 ERROR    self.handles = get_handle(
2025-05-31 22:07:55,837 ERROR    ^^^^^^^^^^^
2025-05-31 22:07:55,837 ERROR    File "/opt/coreflow/.venv/lib/python3.12/site-packages/pandas/io/common.py", line 873, in get_handle
2025-05-31 22:07:55,837 ERROR    handle = open(
2025-05-31 22:07:55,837 ERROR    ^^^^^
2025-05-31 22:07:55,837 ERROR    FileNotFoundError: [Errno 2] No such file or directory: 'market_data.csv'
2025-05-31 22:07:55,837 ERROR    
2025-05-31 22:08:00,907 INFO     Watchdog terminated.
2025-05-31 22:11:03,713 INFO     Started: PID 493189
2025-05-31 22:11:03,919 ERROR    2025-05-31 22:11:03,919 | INFO | üß† Starting CoreFlow Institutional Trading System
2025-05-31 22:11:03,951 ERROR    2025-05-31 22:11:03,951 | INFO | üöÄ Starting Institutional Health Monitor
2025-05-31 22:11:03,951 ERROR    2025-05-31 22:11:03,951 | INFO | üöÄ Starting Institutional Health Monitor
2025-05-31 22:11:03,954 ERROR    2025-05-31 22:11:03,954 | ERROR | Unexpected error: 'high'
2025-05-31 22:11:03,954 ERROR    Traceback (most recent call last):
2025-05-31 22:11:03,954 ERROR    File "/opt/coreflow/.venv/lib/python3.12/site-packages/pandas/core/indexes/base.py", line 3805, in get_loc
2025-05-31 22:11:03,954 ERROR    return self._engine.get_loc(casted_key)
2025-05-31 22:11:03,954 ERROR    ^^^^^^^^^^^^^^^^^^^^^^^^^^^^^^^^
2025-05-31 22:11:03,954 ERROR    File "index.pyx", line 167, in pandas._libs.index.IndexEngine.get_loc
2025-05-31 22:11:03,954 ERROR    File "index.pyx", line 196, in pandas._libs.index.IndexEngine.get_loc
2025-05-31 22:11:03,954 ERROR    File "pandas/_libs/hashtable_class_helper.pxi", line 7081, in pandas._libs.hashtable.PyObjectHashTable.get_item
2025-05-31 22:11:03,954 ERROR    File "pandas/_libs/hashtable_class_helper.pxi", line 7089, in pandas._libs.hashtable.PyObjectHashTable.get_item
2025-05-31 22:11:03,954 ERROR    KeyError: 'high'
2025-05-31 22:11:03,954 ERROR    
2025-05-31 22:11:03,954 ERROR    The above exception was the direct cause of the following exception:
2025-05-31 22:11:03,954 ERROR    
2025-05-31 22:11:03,954 ERROR    Traceback (most recent call last):
2025-05-31 22:11:03,954 ERROR    File "/opt/coreflow/coreflow_main.py", line 97, in main_loop
2025-05-31 22:11:03,954 ERROR    signals = engine.generate_signals(df)
2025-05-31 22:11:03,955 ERROR    ^^^^^^^^^^^^^^^^^^^^^^^^^^^
2025-05-31 22:11:03,955 ERROR    File "/opt/coreflow/core/strategy/valg_engine.py", line 53, in generate_signals
2025-05-31 22:11:03,955 ERROR    df['volatility'] = self._calculate_volatility(df['high'], df['low'], df['close'])
2025-05-31 22:11:03,955 ERROR    ~~^^^^^^^^
2025-05-31 22:11:03,955 ERROR    File "/opt/coreflow/.venv/lib/python3.12/site-packages/pandas/core/frame.py", line 4102, in __getitem__
2025-05-31 22:11:03,955 ERROR    indexer = self.columns.get_loc(key)
2025-05-31 22:11:03,955 ERROR    ^^^^^^^^^^^^^^^^^^^^^^^^^
2025-05-31 22:11:03,955 ERROR    File "/opt/coreflow/.venv/lib/python3.12/site-packages/pandas/core/indexes/base.py", line 3812, in get_loc
2025-05-31 22:11:03,955 ERROR    raise KeyError(key) from err
2025-05-31 22:11:03,955 ERROR    KeyError: 'high'
2025-05-31 22:11:03,955 ERROR    
2025-05-31 22:11:10,830 INFO     Watchdog terminated.
2025-05-31 22:12:17,147 INFO     Started: PID 493355
2025-05-31 22:12:17,339 ERROR    2025-05-31 22:12:17,339 | INFO | üß† Starting CoreFlow Institutional Trading System
2025-05-31 22:12:17,371 ERROR    2025-05-31 22:12:17,371 | INFO | üöÄ Starting Institutional Health Monitor
2025-05-31 22:12:17,371 ERROR    2025-05-31 22:12:17,371 | INFO | üöÄ Starting Institutional Health Monitor
2025-05-31 22:12:25,975 INFO     Watchdog terminated.
